---
title: Python crashes and displays an error message indicating that a process might have been ongoing in another thread at the time of fork() when using multiprocessing
authors:
- smart_coder
tags:
- python
- knowledge
thumbnail: images/python.png
created_at: 2023-03-12 00:00:00
updated_at: 2023-03-12 00:00:00
tldr: The multiprocessing module in Python cannot be used on platforms that do not support the fork() system call, such as Windows, and it can cause errors if used improperly on platforms that do support it due to the way in which it creates new processes.
---

**Contents**

[TOC]

## Introduction
Multiprocessing is a great tool that Python provides for handling CPU-intensive tasks. It allows us to execute multiple processes simultaneously, thus improving the performance of the application. However, sometimes the use of multiprocessing can cause the Python interpreter to crash, and an error message can appear. One such error is "may have been in progress in another thread when fork() was called." In this article, we will discuss what causes this error and how to fix it.

## Explanation
The "may have been in progress in another thread when fork() was called" error occurs when two or more threads are executing in a process, and the process attempts to fork a child process using the fork() system call. The fork() system call creates a new process by duplicating the calling process. If there are multiple threads running in a process, it can be difficult for the operating system to properly duplicate the state of each thread in the new process, resulting in the crash of the Python interpreter.

## Solution
The solution to this problem is to ensure that there are no active threads in the process when the fork() system call is made. To do this, we can use Python's multiprocessing module. The multiprocessing module provides a Process class that can be used to spawn new processes, and each process runs in its own address space. This means that we can avoid the problem of active threads in the parent process interfering with the child process.

Here is an example of how to use the multiprocessing module to avoid this error:

```
from multiprocessing import Process

def my_function():
    print("Hello from child process")

if __name__ == '__main__':
    p = Process(target=my_function)
    p.start()
    p.join()
```

In this example, we create a new process using the Process class, and we specify the target function to be executed in the child process. We then call the start() method to start the process and the join() method to wait for the process to finish.

## Conclusion
In conclusion, the "may have been in progress in another thread when fork() was called" error occurs when there are active threads in a process when the fork() system call is made. This can be avoided by using the multiprocessing module to spawn new processes, where each process runs in its own address space. By doing this, we can ensure that there are no active threads in the parent process interfering with the child process, and we can avoid the crash of the Python interpreter.
